<?xml version="1.0" encoding="UTF-8"?>
<testng-results skipped="1" failed="0" total="3" passed="2">
  <reporter-output>
  </reporter-output>
  <suite name="My Sample Suite" duration-ms="311" started-at="2016-01-11T19:55:57Z" finished-at="2016-01-11T19:55:57Z">
    <groups>
    </groups>
    <test name="Login" duration-ms="311" started-at="2016-01-11T19:55:57Z" finished-at="2016-01-11T19:55:57Z">
      <class name="testng_listeners.logintest">
        <test-method status="FAIL" signature="xyzdata()[pri:1, instance:testng_listeners.logintest@1ff8b8f]" name="xyzdata" duration-ms="119" started-at="2016-01-12T01:25:57Z" finished-at="2016-01-12T01:25:57Z">
          <exception class="java.lang.AssertionError">
            <message>
              <![CDATA[expected [rudra] but found [anjali]]]>
            </message>
            <full-stacktrace>
              <![CDATA[java.lang.AssertionError: expected [rudra] but found [anjali]
	at org.testng.Assert.fail(Assert.java:94)
	at org.testng.Assert.failNotEquals(Assert.java:513)
	at org.testng.Assert.assertEqualsImpl(Assert.java:135)
	at org.testng.Assert.assertEquals(Assert.java:116)
	at org.testng.Assert.assertEquals(Assert.java:190)
	at org.testng.Assert.assertEquals(Assert.java:200)
	at testng_listeners.logintest.xyzdata(logintest.java:12)
	at sun.reflect.NativeMethodAccessorImpl.invoke0(Native Method)
	at sun.reflect.NativeMethodAccessorImpl.invoke(NativeMethodAccessorImpl.java:62)
	at sun.reflect.DelegatingMethodAccessorImpl.invoke(DelegatingMethodAccessorImpl.java:43)
	at java.lang.reflect.Method.invoke(Method.java:497)
	at org.testng.internal.MethodInvocationHelper.invokeMethod(MethodInvocationHelper.java:86)
	at org.testng.internal.Invoker.invokeMethod(Invoker.java:645)
	at org.testng.internal.Invoker.invokeTestMethod(Invoker.java:822)
	at org.testng.internal.Invoker.invokeTestMethods(Invoker.java:1130)
	at org.testng.internal.TestMethodWorker.invokeTestMethods(TestMethodWorker.java:129)
	at org.testng.internal.TestMethodWorker.run(TestMethodWorker.java:112)
	at org.testng.TestRunner.privateRun(TestRunner.java:782)
	at org.testng.TestRunner.run(TestRunner.java:632)
	at org.testng.SuiteRunner.runTest(SuiteRunner.java:366)
	at org.testng.SuiteRunner.runSequentially(SuiteRunner.java:361)
	at org.testng.SuiteRunner.privateRun(SuiteRunner.java:319)
	at org.testng.SuiteRunner.run(SuiteRunner.java:268)
	at org.testng.SuiteRunnerWorker.runSuite(SuiteRunnerWorker.java:52)
	at org.testng.SuiteRunnerWorker.run(SuiteRunnerWorker.java:86)
	at org.testng.TestNG.runSuitesSequentially(TestNG.java:1244)
	at org.testng.TestNG.runSuitesLocally(TestNG.java:1169)
	at org.testng.TestNG.run(TestNG.java:1064)
	at org.testng.remote.RemoteTestNG.run(RemoteTestNG.java:113)
	at org.testng.remote.RemoteTestNG.initAndRun(RemoteTestNG.java:206)
	at org.testng.remote.RemoteTestNG.main(RemoteTestNG.java:177)
]]>
            </full-stacktrace>
          </exception> <!-- java.lang.AssertionError -->
          <reporter-output>
          </reporter-output>
        </test-method> <!-- xyzdata -->
        <test-method status="SKIP" signature="xyzdataparttial()[pri:2, instance:testng_listeners.logintest@1ff8b8f]" name="xyzdataparttial" duration-ms="0" started-at="2016-01-12T01:25:57Z" depends-on-methods="testng_listeners.logintest.xyzdata" finished-at="2016-01-12T01:25:57Z">
          <exception class="java.lang.Throwable">
            <message>
              <![CDATA[Method logintest.xyzdataparttial()[pri:2, instance:testng_listeners.logintest@1ff8b8f] depends on not successfully finished methods]]>
            </message>
            <full-stacktrace>
              <![CDATA[java.lang.Throwable: Method logintest.xyzdataparttial()[pri:2, instance:testng_listeners.logintest@1ff8b8f] depends on not successfully finished methods
	at org.testng.internal.Invoker.invokeTestMethods(Invoker.java:1039)
	at org.testng.internal.TestMethodWorker.invokeTestMethods(TestMethodWorker.java:129)
	at org.testng.internal.TestMethodWorker.run(TestMethodWorker.java:112)
	at org.testng.TestRunner.privateRun(TestRunner.java:782)
	at org.testng.TestRunner.run(TestRunner.java:632)
	at org.testng.SuiteRunner.runTest(SuiteRunner.java:366)
	at org.testng.SuiteRunner.runSequentially(SuiteRunner.java:361)
	at org.testng.SuiteRunner.privateRun(SuiteRunner.java:319)
	at org.testng.SuiteRunner.run(SuiteRunner.java:268)
	at org.testng.SuiteRunnerWorker.runSuite(SuiteRunnerWorker.java:52)
	at org.testng.SuiteRunnerWorker.run(SuiteRunnerWorker.java:86)
	at org.testng.TestNG.runSuitesSequentially(TestNG.java:1244)
	at org.testng.TestNG.runSuitesLocally(TestNG.java:1169)
	at org.testng.TestNG.run(TestNG.java:1064)
	at org.testng.remote.RemoteTestNG.run(RemoteTestNG.java:113)
	at org.testng.remote.RemoteTestNG.initAndRun(RemoteTestNG.java:206)
	at org.testng.remote.RemoteTestNG.main(RemoteTestNG.java:177)
]]>
            </full-stacktrace>
          </exception> <!-- java.lang.Throwable -->
          <reporter-output>
          </reporter-output>
        </test-method> <!-- xyzdataparttial -->
        <test-method status="PASS" signature="xyzdatawhole()[pri:3, instance:testng_listeners.logintest@1ff8b8f]" name="xyzdatawhole" duration-ms="1" started-at="2016-01-12T01:25:57Z" finished-at="2016-01-12T01:25:57Z">
          <reporter-output>
          </reporter-output>
        </test-method> <!-- xyzdatawhole -->
      </class> <!-- testng_listeners.logintest -->
    </test> <!-- Login -->
  </suite> <!-- My Sample Suite -->
</testng-results>
